<?xml version="1.0"?>
<robot name="PLATAFORMA">
    <link name="robot_base">
        <inertial>
            <origin rpy="-3.140161 3.141620 3.141424" xyz="-0.112566 -0.824982 0.283321" />
            <inertia izz="2.6040184849823" iyy="2.4203830810776" ixy="-0.00027925598521436" ixz="0.043226697793656" iyz="0.00034156589289172" ixx="1.2700013957142" />
            <mass value="20.0" />
        </inertial>
        <collision name="PLATAFORMA">
            <origin rpy="-3.141593 3.141593 -3.141593" xyz="-0.424705 -1.017470 -0.000000" />
            <geometry>
                <mesh filename="file:///home/jibacem/MASTER/TFM/modelo/STLS/CUERPO.STL" />
            </geometry>
        </collision>
        <visual name="CUERPO">
            <origin rpy="-3.141593 3.141593 -3.141593" xyz="-0.424705 -1.017470 -0.000000" />
            <geometry>
                <mesh filename="file:///home/jibacem/MASTER/TFM/modelo/STLS/CUERPO.STL" />
            </geometry>
            <material name="CUERPO_material">
                <color rgba="0.360000 0.360000 0.360000 1.0" />
            </material>
        </visual>
    </link>
    <joint name="back_left_wheel" type="continuous">
        <axis xyz="0 0 1" />
        <parent link="robot_base" />
        <child link="RUEDA_RL" />
        <origin rpy="-1.570796 2.967059 0.000008" xyz="-0.339619 -0.590969 0.117800" />
    </joint>
    <link name="RUEDA_RL">
        <inertial>
            <origin rpy="3.141585 3.141592 -1.396263" xyz="-0.095669 -0.136487 -0.234031" />
            <inertia izz="0.16482" iyy="0.16482" ixy="0.0" ixz="-4.269e-05" iyz="0.0" ixx="0.24267" />
            <mass value="3.0" />
        </inertial>
        <collision name="RUEDA_RL">
            <origin rpy="3.141585 3.141592 -1.396263" xyz="-0.095669 -0.136487 -0.234031" />
            <geometry>
                <mesh filename="file:///home/jibacem/MASTER/TFM/modelo/STLS/RUEDA_RL.STL" />
            </geometry>
        </collision>
        <visual name="RUEDA_RL">
            <origin rpy="3.141585 3.141592 -1.396263" xyz="-0.095669 -0.136487 -0.234031" />
            <geometry>
                <mesh filename="file:///home/jibacem/MASTER/TFM/modelo/STLS/RUEDA_RL.STL" />
            </geometry>
            <material name="RUEDA_RL_material">
                <color rgba="0.190000 0.190000 0.190000 1.0" />
            </material>
        </visual>
    </link>
    <joint name="front_left_wheel" type="continuous">
        <axis xyz="0 0 1" />
        <parent link="robot_base" />
        <child link="RUEDA_FL" />
        <origin rpy="-1.570789 3.316125 0.000007" xyz="0.141368 -0.590968 0.117805" />
    </joint>
    <link name="RUEDA_FL">
        <inertial>
            <origin rpy="-3.141586 3.141584 -0.174532" xyz="0.217246 -0.157931 -0.234029" />
            <inertia izz="0.16482" iyy="0.16482" ixy="0.0" ixz="-4.269e-05" iyz="0.0" ixx="0.24267" />
            <mass value="3.0" />
        </inertial>
        <collision name="RUEDA_FL">
            <origin rpy="-3.141586 3.141584 -0.174532" xyz="0.217246 -0.157931 -0.234029" />
            <geometry>
                <mesh filename="file:///home/jibacem/MASTER/TFM/modelo/STLS/RUEDA_FL.STL" />
            </geometry>
        </collision>
        <visual name="RUEDA_FL">
            <origin rpy="-3.141586 3.141584 -0.174532" xyz="0.217246 -0.157931 -0.234029" />
            <geometry>
                <mesh filename="file:///home/jibacem/MASTER/TFM/modelo/STLS/RUEDA_FL.STL" />
            </geometry>
            <material name="RUEDA_FL_material">
                <color rgba="0.190000 0.190000 0.190000 1.0" />
            </material>
        </visual>
    </link>
    <joint name="back_right_wheel" type="continuous">
        <axis xyz="0 0 1" />
        <parent link="robot_base" />
        <child link="RUEDA_RR" />
        <origin rpy="1.570773 4.537856 0.000024" xyz="-0.339618 -1.058970 0.117805" />
    </joint>
    <link name="RUEDA_RR">
        <inertial>
            <origin rpy="1.570792 3.141594 1.396263" xyz="-0.095616 0.136148 0.071231" />
            <inertia izz="0.16482" iyy="0.16482" ixy="0.0" ixz="-4.269e-05" iyz="0.0" ixx="0.24267" />
            <mass value="3.0" />
        </inertial>
        <collision name="RUEDA_RR">
            <origin rpy="1.570792 3.141594 1.396263" xyz="-0.095616 0.136148 0.071231" />
            <geometry>
                <mesh filename="file:///home/jibacem/MASTER/TFM/modelo/STLS/RUEDA_RR.STL" />
            </geometry>
        </collision>
        <visual name="RUEDA_RR">
            <origin rpy="1.570792 3.141594 1.396263" xyz="-0.095616 0.136148 0.071231" />
            <geometry>
                <mesh filename="file:///home/jibacem/MASTER/TFM/modelo/STLS/RUEDA_RR.STL" />
            </geometry>
            <material name="RUEDA_RR_material">
                <color rgba="0.190000 0.190000 0.190000 1.0" />
            </material>
        </visual>
    </link>
    <joint name="front_right_wheel" type="continuous">
        <axis xyz="0 0 1" />
        <parent link="robot_base" />
        <child link="RUEDA_FR" />
        <origin rpy="-1.570795 2.967060 -3.141578" xyz="0.141369 -1.058968 0.117806" />
    </joint>
    <link name="RUEDA_FR">
        <inertial>
            <origin rpy="1.570795 3.141607 -2.967060" xyz="-0.217241 -0.157929 0.071228" />
            <inertia izz="0.16482" iyy="0.16482" ixy="0.0" ixz="-4.269e-05" iyz="0.0" ixx="0.24267" />
            <mass value="3.0" />
        </inertial>
        <collision name="RUEDA_FR">
            <origin rpy="1.570795 3.141607 -2.967060" xyz="-0.217241 -0.157929 0.071228" />
            <geometry>
                <mesh filename="file:///home/jibacem/MASTER/TFM/modelo/STLS/RUEDA_FR.STL" />
            </geometry>
        </collision>
        <visual name="RUEDA_FR">
            <origin rpy="1.570795 3.141607 -2.967060" xyz="-0.217241 -0.157929 0.071228" />
            <geometry>
              <mesh filename="file:///home/jibacem/MASTER/TFM/modelo/STLS/RUEDA_FR.STL" />
            </geometry>
            <material name="RUEDA_FR_material">
                <color rgba="0.190000 0.190000 0.190000 1.0" />
            </material>
        </visual>
    </link>
    <joint name="AR_joint_1" type="revolute">
        <axis xyz="0 0 1" />
        <limit velocity="3.1415927410126" upper="6.2831854820251" lower="-6.2831854820251" effort="50.0" />
        <parent link="robot_base" />
        <child link="AR_link_1" />
        <origin rpy="-3.141593 3.141593 -0.000000" xyz="0.025000 -0.925000 0.422498" />
    </joint>
    <link name="AR_link_1">
        <inertial>
            <origin rpy="-3.141593 3.141593 1.570796" xyz="-0.046108 0.057110 -0.148868" />
            <inertia izz="0.00994" iyy="0.0141" ixy="2.844e-09" ixz="0.00034" iyz="1.168e-06" ixx="0.01332" />
            <mass value="1.0" />
        </inertial>
        <collision name="AR_link_1">
            <origin rpy="-3.141593 3.141593 1.570796" xyz="-0.046178 0.053990 -0.147498" />
            <geometry>
                <mesh filename="file:///home/jibacem/MASTER/TFM/modelo/STLS/link_1.STL" />
            </geometry>
        </collision>
        <visual name="AR_link_1">
            <origin rpy="-3.141593 3.141593 1.570796" xyz="-0.046178 0.053990 -0.147498" />
            <geometry>
                <mesh filename="file:///home/jibacem/MASTER/TFM/modelo/STLS/link_1.STL" />
            </geometry>
            <material name="AR_link_1_material">
                <color rgba="0.730400 0.149600 0.149600 1.0" />
            </material>
        </visual>
    </link>
    <joint name="AR_joint_2" type="revolute">
        <axis xyz="0 0 1" />
        <limit velocity="3.1415927410126" upper="6.2831854820251" lower="-6.2831854820251" effort="50.0" />
        <parent link="AR_link_1" />
        <child link="AR_link_2" />
        <origin rpy="1.570795 3.141593 3.141593" xyz="-0.000031 0.111666 0.004400" />
    </joint>
    <link name="AR_link_2">
        <inertial>
            <origin rpy="1.570796 1.570796 0.000000" xyz="-0.045956 0.151901 0.069134" />
            <inertia izz="0.03455" iyy="0.188125" ixy="1.469e-05" ixz="0.008" iyz="4.695e-05" ixx="0.17735" />
            <mass value="2.5" />
        </inertial>
        <collision name="AR_link_2">
            <origin rpy="1.570796 1.570796 0.000000" xyz="-0.045866 0.151901 0.066334" />
            <geometry>
                <mesh filename="file:///home/jibacem/MASTER/TFM/modelo/STLS/link_2.STL" />
            </geometry>
        </collision>
        <visual name="AR_link_2">
            <origin rpy="1.570796 1.570796 0.000000" xyz="-0.045866 0.151901 0.066334" />
            <geometry>
               <mesh filename="file:///home/jibacem/MASTER/TFM/modelo/STLS/link_2.STL" />
            </geometry>
            <material name="AR_link_2_material">
                <color rgba="0.000000 0.880000 0.000000 1.0" />
            </material>
        </visual>
    </link>
    <joint name="AR_joint_3" type="revolute">
        <axis xyz="0 0 1" />
        <limit velocity="3.1415927410126" upper="6.2831854820251" lower="-6.2831854820251" effort="50.0" />
        <parent link="AR_link_2" />
        <child link="AR_link_3" />
        <origin rpy="3.141593 3.141593 3.141593" xyz="0.000076 -0.243650 -0.000000" />
    </joint>
    <link name="AR_link_3">
        <inertial>
            <origin rpy="1.570796 1.570796 0.000000" xyz="-0.037772 0.395549 -0.027774" />
            <inertia izz="0.0194" iyy="0.1285" ixy="-2.29625e-05" ixz="-0.0073" iyz="-2.1975e-05" ixx="0.123825" />
            <mass value="2.5" />
        </inertial>
        <collision name="AR_link_3">
            <origin rpy="1.570796 1.570796 0.000000" xyz="-0.037832 0.395549 -0.034024" />
            <geometry>
                <mesh filename="file:///home/jibacem/MASTER/TFM/modelo/STLS/link_3.STL" />
            </geometry>
        </collision>
        <visual name="AR_link_3">
            <origin rpy="1.570796 1.570796 0.000000" xyz="-0.037832 0.395549 -0.034024" />
            <geometry>
                <mesh filename="file:///home/jibacem/MASTER/TFM/modelo/STLS/link_3.STL" />
            </geometry>
            <material name="AR_link_3_material">
                <color rgba="0.000000 0.000000 0.690000 1.0" />
            </material>
        </visual>
    </link>
    <joint name="AR_joint_4" type="revolute">
        <axis xyz="0 0 1" />
        <limit velocity="6.2831854820251" upper="6.2831854820251" lower="-6.2831854820251" effort="50.0" />
        <parent link="AR_link_3" />
        <child link="AR_link_4" />
        <origin rpy="-3.141591 3.141593 -3.141593" xyz="-0.000045 -0.213250 -0.000001" />
    </joint>
    <link name="AR_link_4">
        <inertial>
            <origin rpy="1.570796 1.570796 0.000000" xyz="-0.032560 0.607349 0.031251" />
            <inertia izz="0.00463" iyy="0.00762" ixy="-1.302e-06" ixz="4.444e-05" iyz="1.933e-05" ixx="0.00746" />
            <mass value="1.0" />
        </inertial>
        <collision name="AR_link_4">
            <origin rpy="1.570796 1.570796 0.000000" xyz="-0.032440 0.608799 0.033231" />
            <geometry>
                <mesh filename="file:///home/jibacem/MASTER/TFM/modelo/STLS/link_4.STL" />
            </geometry>
        </collision>
        <visual name="AR_link_4">
            <origin rpy="1.570796 1.570796 0.000000" xyz="-0.032440 0.608799 0.033231" />
            <geometry>
               <mesh filename="file:///home/jibacem/MASTER/TFM/modelo/STLS/link_4.STL" />
            </geometry>
            <material name="AR_link_4_material">
                <color rgba="0.910000 0.910000 0.000000 1.0" />
            </material>
        </visual>
    </link>
    <joint name="AR_joint_5" type="revolute">
        <axis xyz="0 0 1" />
        <limit velocity="6.2831854820251" upper="6.2831854820251" lower="-6.2831854820251" effort="50.0" />
        <parent link="AR_link_4" />
        <child link="AR_link_5" />
        <origin rpy="-1.570796 3.141593 3.141593" xyz="-0.000000 -0.084218 0.000684" />
    </joint>
    <link name="AR_link_5">
        <inertial>
            <origin rpy="-3.141593 3.141593 1.570796" xyz="-0.032237 0.051158 -0.694827" />
            <inertia izz="0.0076" iyy="0.00779" ixy="1.025e-05" ixz="7.433e-05" iyz="-2.57e-06" ixx="0.00467" />
            <mass value="1.0" />
        </inertial>
        <collision name="AR_link_5">
            <origin rpy="-3.141593 3.141593 1.570796" xyz="-0.032337 0.049698 -0.693017" />
            <geometry>
                <mesh filename="file:///home/jibacem/MASTER/TFM/modelo/STLS/link_5.STL" />
            </geometry>
        </collision>
        <visual name="AR_link_5">
            <origin rpy="-3.141593 3.141593 1.570796" xyz="-0.032337 0.049698 -0.693017" />
            <geometry>
                <mesh filename="file:///home/jibacem/MASTER/TFM/modelo/STLS/link_5.STL" />
            </geometry>
            <material name="AR_link_5_material">
                <color rgba="0.740000 0.000000 0.740000 1.0" />
            </material>
        </visual>
    </link>
    <joint name="AR_joint_6" type="continuous">
        <axis xyz="0 0 1" />
        <parent link="AR_link_5" />
        <child link="AR_link_6" />
        <origin rpy="1.570796 3.141593 -3.141593" xyz="-0.000000 -0.000684 0.001132" />
    </joint>
    <link name="AR_link_6">
        <inertial>
            <origin rpy="1.570796 1.570796 0.000000" xyz="-0.032340 0.694149 0.088334" />
            <inertia izz="0.00387" iyy="0.00262" ixy="0.0" ixz="0.0" iyz="0.0" ixx="0.00262" />
            <mass value="1.0" />
        </inertial>
        <collision name="AR_link_6">
            <origin rpy="1.570796 1.570796 0.000000" xyz="-0.032340 0.694149 0.088334" />
            <geometry>
               <mesh filename="file:///home/jibacem/MASTER/TFM/modelo/STLS/link_6.STL" />
            </geometry>
        </collision>
        <visual name="AR_link_6">
            <origin rpy="1.570796 1.570796 0.000000" xyz="-0.032340 0.694149 0.088334" />
            <geometry>
                <mesh filename="file:///home/jibacem/MASTER/TFM/modelo/STLS/link_6.STL" />
            </geometry>
            <material name="AR_link_6_material">
                <color rgba="0.000000 0.880000 0.880000 1.0" />
            </material>
        </visual>
    </link>
    <joint name="AL_joint_1" type="revolute">
        <axis xyz="0 0 1" />
        <limit velocity="3.1415927410126" upper="6.2831854820251" lower="-6.2831854820251" effort="50.0" />
        <parent link="robot_base" />
        <child link="AL_link_1" />
        <origin rpy="3.141593 3.141593 -3.141593" xyz="0.025000 -0.725000 0.422498" />
    </joint>
    <link name="AL_link_1">
        <inertial>
            <origin rpy="-3.141593 3.141593 1.570796" xyz="-0.046108 0.057110 -0.148868" />
            <inertia izz="0.00994" iyy="0.0141" ixy="2.844e-09" ixz="0.00034" iyz="1.168e-06" ixx="0.01332" />
            <mass value="1.0" />
        </inertial>
        <collision name="AL_link_1">
            <origin rpy="-3.141593 3.141593 1.570796" xyz="-0.046178 0.053990 -0.147498" />
            <geometry>
                <mesh filename="file:///home/jibacem/MASTER/TFM/modelo/STLS/link_1.STL" />
            </geometry>
        </collision>
        <visual name="AL_link_1">
            <origin rpy="-3.141593 3.141593 1.570796" xyz="-0.046178 0.053990 -0.147498" />
            <geometry>
                <mesh filename="file:///home/jibacem/MASTER/TFM/modelo/STLS/link_1.STL" />
            </geometry>
            <material name="AL_link_1_material">
                <color rgba="0.730000 0.150000 0.150000 1.0" />
            </material>
        </visual>
    </link>
    <joint name="AL_joint_2" type="revolute">
        <axis xyz="0 0 1" />
        <limit velocity="3.1415927410126" upper="6.2831854820251" lower="-6.2831854820251" effort="50.0" />
        <parent link="AL_link_1" />
        <child link="AL_link_2" />
        <origin rpy="1.570795 3.141593 3.141593" xyz="-0.000031 0.111666 0.004400" />
    </joint>
    <link name="AL_link_2">
        <inertial>
            <origin rpy="1.570796 1.570796 0.000000" xyz="-0.045956 0.151901 0.069134" />
            <inertia izz="0.03455" iyy="0.188125" ixy="1.469e-05" ixz="0.008" iyz="4.695e-05" ixx="0.17735" />
            <mass value="2.5" />
        </inertial>
        <collision name="AL_link_2">
            <origin rpy="1.570796 1.570796 0.000000" xyz="-0.045866 0.151901 0.066334" />
            <geometry>
                <mesh filename="file:///home/jibacem/MASTER/TFM/modelo/STLS/link_2.STL" />
            </geometry>
        </collision>
        <visual name="AL_link_2">
            <origin rpy="1.570796 1.570796 0.000000" xyz="-0.045866 0.151901 0.066334" />
            <geometry>
               <mesh filename="file:///home/jibacem/MASTER/TFM/modelo/STLS/link_2.STL" />
            </geometry>
            <material name="AL_link_2_material">
                <color rgba="0.000000 0.880000 0.000000 1.0" />
            </material>
        </visual>
    </link>
    <joint name="AL_joint_3" type="revolute">
        <axis xyz="0 0 1" />
        <limit velocity="3.1415927410126" upper="6.2831854820251" lower="-6.2831854820251" effort="50.0" />
        <parent link="AL_link_2" />
        <child link="AL_link_3" />
        <origin rpy="-3.141593 3.141593 3.141593" xyz="0.000076 -0.243650 -0.000000" />
    </joint>
    <link name="AL_link_3">
        <inertial>
            <origin rpy="1.570796 1.570796 0.000000" xyz="-0.037772 0.395549 -0.027774" />
            <inertia izz="0.0194" iyy="0.1285" ixy="-2.29625e-05" ixz="-0.0073" iyz="-2.1975e-05" ixx="0.123825" />
            <mass value="2.5" />
        </inertial>
        <collision name="AL_link_3">
            <origin rpy="1.570796 1.570796 0.000000" xyz="-0.037832 0.395549 -0.034024" />
            <geometry>
                <mesh filename="file:///home/jibacem/MASTER/TFM/modelo/STLS/link_3.STL" />
            </geometry>
        </collision>
        <visual name="AL_link_3">
            <origin rpy="1.570796 1.570796 0.000000" xyz="-0.037832 0.395549 -0.034024" />
            <geometry>
                <mesh filename="file:///home/jibacem/MASTER/TFM/modelo/STLS/link_3.STL" />
            </geometry>
            <material name="AL_link_3_material">
                <color rgba="0.000000 0.000000 0.690000 1.0" />
            </material>
        </visual>
    </link>
    <joint name="AL_joint_4" type="revolute">
        <axis xyz="0 0 1" />
        <limit velocity="6.2831854820251" upper="6.2831854820251" lower="-6.2831854820251" effort="50.0" />
        <parent link="AL_link_3" />
        <child link="AL_link_4" />
        <origin rpy="-3.141591 3.141593 -3.141593" xyz="-0.000045 -0.213250 -0.000001" />
    </joint>
    <link name="AL_link_4">
        <inertial>
            <origin rpy="1.570796 1.570796 0.000000" xyz="-0.032560 0.607349 0.031251" />
            <inertia izz="0.00463" iyy="0.00762" ixy="-1.302e-06" ixz="4.444e-05" iyz="1.933e-05" ixx="0.00746" />
            <mass value="1.0" />
        </inertial>
        <collision name="AL_link_4">
            <origin rpy="1.570796 1.570796 0.000000" xyz="-0.032440 0.608799 0.033231" />
            <geometry>
                <mesh filename="file:///home/jibacem/MASTER/TFM/modelo/STLS/link_4.STL" />
            </geometry>
        </collision>
        <visual name="AL_link_4">
            <origin rpy="1.570796 1.570796 0.000000" xyz="-0.032440 0.608799 0.033231" />
            <geometry>
                <mesh filename="file:///home/jibacem/MASTER/TFM/modelo/STLS/link_4.STL" />
            </geometry>
            <material name="AL_link_4_material">
                <color rgba="0.910000 0.910000 0.000000 1.0" />
            </material>
        </visual>
    </link>
    <joint name="AL_joint_5" type="revolute">
        <axis xyz="0 0 1" />
        <limit velocity="6.2831854820251" upper="6.2831854820251" lower="-6.2831854820251" effort="50.0" />
        <parent link="AL_link_4" />
        <child link="AL_link_5" />
        <origin rpy="-1.570796 3.141593 3.141593" xyz="-0.000000 -0.084218 0.000684" />
    </joint>
    <link name="AL_link_5">
        <inertial>
            <origin rpy="-3.141593 3.141593 1.570796" xyz="-0.032237 0.051158 -0.694827" />
            <inertia izz="0.0076" iyy="0.00779" ixy="1.025e-05" ixz="7.433e-05" iyz="-2.57e-06" ixx="0.00467" />
            <mass value="1.0" />
        </inertial>
        <collision name="AL_link_5">
            <origin rpy="-3.141593 3.141593 1.570796" xyz="-0.032337 0.049698 -0.693017" />
            <geometry>
                <mesh filename="file:///home/jibacem/MASTER/TFM/modelo/STLS/link_5.STL" />
            </geometry>
        </collision>
        <visual name="AL_link_5">
            <origin rpy="-3.141593 3.141593 1.570796" xyz="-0.032337 0.049698 -0.693017" />
            <geometry>
                <mesh filename="file:///home/jibacem/MASTER/TFM/modelo/STLS/link_5.STL" />
            </geometry>
            <material name="AL_link_5_material">
                <color rgba="0.740000 0.000000 0.740000 1.0" />
            </material>
        </visual>
    </link>
    <joint name="AL_joint_6" type="continuous">
        <axis xyz="0 0 1" />
        <parent link="AL_link_5" />
        <child link="AL_link_6" />
        <origin rpy="1.570796 3.141593 -3.141593" xyz="-0.000000 -0.000684 0.001132" />
    </joint>
    <link name="AL_link_6">
        <inertial>
            <origin rpy="1.570796 1.570796 0.000000" xyz="-0.032340 0.694149 0.088334" />
            <inertia izz="0.00387" iyy="0.00262" ixy="0.0" ixz="0.0" iyz="0.0" ixx="0.00262" />
            <mass value="1.0" />
        </inertial>
        <collision name="AL_link_6">
            <origin rpy="1.570796 1.570796 0.000000" xyz="-0.032340 0.694149 0.088334" />
            <geometry>
                <mesh filename="file:///home/jibacem/MASTER/TFM/modelo/STLS/link_6.STL" />
            </geometry>
        </collision>
        <visual name="AL_link_6">
            <origin rpy="1.570796 1.570796 0.000000" xyz="-0.032340 0.694149 0.088334" />
            <geometry>
                <mesh filename="file:///home/jibacem/MASTER/TFM/modelo/STLS/link_6.STL" />
            </geometry>
            <material name="AL_link_6_material">
                <color rgba="0.000000 0.880000 0.880000 1.0" />
            </material>
        </visual>
    </link>
</robot>
